<?xml version="1.0"?>
<robot name="tracked_robot" xmlns:xacro="http://ros.org/wiki/xacro">
    <xacro:include filename="camera.urdf.xacro" />
    <xacro:macro name="hand"  params="parent">
        <joint name="hand_base_joint" type="fixed">
            <origin xyz="0.04 0 0.14" rpy="0 0 0" />
            <parent link="${parent}"/>
            <child link="hand_base"/>
            <axis xyz="0 0 1" />
        </joint>
        
        <link name="hand_base">
            <inertial>
                <mass value="0.0001"/>
                <origin rpy=" 0 0 0" xyz="0 0 0"/>
                <inertia ixx="1.6666666666666668e-07" ixy="0" ixz="0" iyy="1.6666666666666668e-07" iyz="0" izz="1.6666666666666668e-07"/>
            </inertial>
            <visual>
                <origin xyz="0 0 0" rpy="0 0 0"/>
                <geometry>
                     <cylinder length="0.12" radius="0.06"/>
                </geometry>
                <material name="Black" />
            </visual>    
        </link>


       <joint name="hand_joint" type="continuous">
            <origin xyz="0 0 0.05" rpy="0 0 0" />
            <parent link="hand_base"/>
            <child link="hand"/>
            <axis xyz="0 0 1" />
        </joint>
        

        <link name="hand">
            <inertial>
                <mass value="0.0001"/>
                <origin rpy=" 0 0 0" xyz="0 0 0"/>
                <inertia ixx="1.6666666666666668e-07" ixy="0" ixz="0" iyy="1.6666666666666668e-07" iyz="0" izz="1.6666666666666668e-07"/>
            </inertial>
            <visual>
                <origin xyz="0.4 0 0" rpy="0 0 0"/>
                <geometry>
                     <box size="0.9 0.1 0.01"/>
                </geometry>
                <material name="Black" />
            </visual>    
        </link>

        <xacro:camera parent="hand" />
    </xacro:macro>
</robot>