<?xml version="1.0"?>
<robot name="tracked_robot" xmlns:xacro="http://ros.org/wiki/xacro">


    <xacro:macro name="track" params="type parent radius diff_drive_emulation mimic_enable">

        <!-- Define orientation -->
        <xacro:if value="${type == 'left'}">
            <xacro:property name="orientation" value="-1" />
        </xacro:if>
        <xacro:if value="${type == 'right'}">
            <xacro:property name="orientation" value="1" />
        </xacro:if>

        <xacro:if value="${mimic_enable}">
            <xacro:property name="mimic_type" value="continuous" />
        </xacro:if>
        <xacro:unless value="${mimic_enable}">
            <xacro:property name="mimic_type" value="fixed" />
        </xacro:unless>

        <xacro:property name="radius_wheel" value="${radius}" />
        <xacro:property name="scale" value="0.0046" />

        <joint name="sprocket_${type}_joint" type="continuous">
            <origin xyz="0.0 ${orientation * -0.235} -0.06" rpy="0 0 0" />
            <parent link="${parent}" />
            <child link="sprocket_${type}" />
            <axis xyz="0 1 0" />

        </joint>

        <link name="sprocket_${type}">
            <inertial>
                <mass value="0.1" />
                <inertia ixx="1e-3" ixy="0.0" ixz="0.0"
                    iyy="1e-3" iyz="0.0"
                    izz="1e-3" />
            </inertial>
            <visual>
                <origin xyz="0 0 0" rpy="${pi/2} 0 0" />
                <geometry>
                    <mesh filename="${path_meshes}/sprocket.stl" scale="${scale} ${scale} ${scale}" />
                    <cylinder length="0.06" radius="${radius_wheel}" />
                </geometry>
                <material name="Black" />
            </visual>
            <!-- Collision cylinder -->
            <collision>
                <origin xyz="0 0 0" rpy="${pi/2} 0 0" />
                <geometry>
                    <cylinder length="0.06" radius="${radius}" />
                </geometry>
                <material name="Black" />
            </collision>
        </link>

        <gazebo reference="sprocket_${type}">
            <material>Gazebo/Blue</material>
            <kp>1e15</kp>
            <kd>1e13</kd>
            <mu1>1000</mu1>
            <mu2>1000</mu2>
            <!-- Ignition color reference -->
            <visual>
                <material>
                    <ambient>0.0 0.0 0.5 1.0</ambient>
                    <diffuse>0.0 0.0 0.5 1.0</diffuse>
                    <specular>0.0 0.0 0.5 1.0</specular>
                </material>
            </visual>
        </gazebo>

        <joint name="wheel_${type}_joint" type="continuous">
            <origin xyz="-0.221 ${orientation * -0.235} -0.06" rpy="0 0 0" />
            <parent link="${parent}" />
            <child link="wheel_${type}" />
            <axis xyz="0 1 0" />
            <mimic joint="sprocket_${type}_joint" multiplier="1" offset="0" />
        </joint>

        <link name="wheel_${type}">
            <inertial>
                <mass value="0.1" />
                <inertia ixx="1e-3" ixy="0.0" ixz="0.0"
                    iyy="1e-3" iyz="0.0"
                    izz="1e-3" />
            </inertial>
            <visual>
                <origin xyz="0 0 0" rpy="${pi/2} 0 0" />
                <geometry>
                    <mesh filename="${path_meshes}/wheel.stl" scale="${scale} ${scale} ${scale}" />
                    <cylinder length="0.06" radius="${radius_wheel}" />
                </geometry>
                <material name="Black" />
            </visual>
            <!-- Collision cylinder -->
            <collision>
                <origin xyz="0 0 0" rpy="${pi/2} 0 0" />
                <geometry>
                    <cylinder length="0.06" radius="${radius_wheel}" />
                </geometry>
                <material name="Black" />
            </collision>
        </link>

        <gazebo reference="wheel_${type}">
            <material>Gazebo/Red</material>
            <kp>1e15</kp>
            <kd>1e13</kd>
            <mu1>1</mu1>
            <mu2>1</mu2>
            <!-- Ignition color reference -->
            <visual>
                <material>
                    <ambient>0.5 0.0 0.0 1.0</ambient>
                    <diffuse>0.5 0.0 0.0 1.0</diffuse>
                    <specular>0.5 0.0 0.0 1.0</specular>
                </material>
            </visual>
        </gazebo>

        <joint name="front_wheel_${type}_joint" type="continuous">
            <origin xyz="0.221 ${orientation * -0.235} -0.06" rpy="0 0 0" />
            <parent link="${parent}" />
            <child link="front_wheel_${type}" />
            <axis xyz="0 1 0" />
            <!-- Passive wheel rotate automatically according to the status of the active one -->
            <mimic joint="sprocket_${type}_joint" multiplier="1" offset="0" />
        </joint>

        <link name="front_wheel_${type}">
            <inertial>
                <mass value="0.1" />
                <inertia ixx="1e-3" ixy="0.0" ixz="0.0"
                    iyy="1e-3" iyz="0.0"
                    izz="1e-3" />
            </inertial>
            <visual>
                <origin xyz="0 0 0" rpy="${pi/2} 0 0" />
                <geometry>
                    <mesh filename="${path_meshes}/wheel.stl" scale="${scale} ${scale} ${scale}" />
                    <cylinder length="0.06" radius="${radius_wheel}" />
                </geometry>
                <material name="Black" />
            </visual>
            <!-- Collision cylinder -->
            <collision>
                <origin xyz="0 0 0" rpy="${pi/2} 0 0" />
                <geometry>
                    <cylinder length="0.06" radius="${radius_wheel}" />
                </geometry>
                <material name="Black" />
            </collision>
        </link>

        <gazebo reference="front_wheel_${type}">
            <material>Gazebo/Red</material>
            <kp>1e15</kp>
            <kd>1e13</kd>
            <mu1>1</mu1>
            <mu2>1</mu2>
            <!-- Ignition color reference -->
            <visual>
                <material>
                    <ambient>0.5 0.0 0.0 1.0</ambient>
                    <diffuse>0.5 0.0 0.0 1.0</diffuse>
                    <specular>0.5 0.0 0.0 1.0</specular>
                </material>
            </visual>
        </gazebo>

        <joint name="track_${type}_joint" type="fixed">
            <origin xyz="0.0 ${orientation * -0.235} -0.05" rpy="0 0 0" />
            <parent link="${parent}" />
            <child link="track_${type}" />
        </joint>

        <link name="track_${type}">
            <inertial>
                <mass value="0.2" />
                <inertia ixx="1e-3" ixy="0.0" ixz="0.0"
                    iyy="1e-3" iyz="0.0"
                    izz="1e-3" />
            </inertial>
            <visual>
                <origin xyz="0 0 0" rpy="0 0 0" />
                <geometry>
                    <mesh filename="${path_meshes}/track.stl" scale="${scale} ${scale} ${scale}" />
                </geometry>
                <material name="Black" />
            </visual>
            <collision>
                <origin xyz="0 0 0" rpy="0 0 0" />
                <geometry>
                    <box size="0.56 0.07 0.12" />
                </geometry>
                <material name="Black" />
            </collision>
        </link>

        <gazebo reference="track_${type}">
            <material>Gazebo/Black</material>
            <kp>1e15</kp>
            <kd>1e13</kd>
            <mu1>0</mu1>
            <mu2>0</mu2>
            <visual>
                <material>
                    <ambient>0.01 0.01 0.01 1.0</ambient>
                    <diffuse>0.01 0.01 0.01 1.0</diffuse>
                    <specular>0.01 0.01 0.01 1.0</specular>
                </material>
            </visual>
        </gazebo>

    </xacro:macro>

</robot>